Creating DB Connection
all last):
  File "C:\Users\arkot\AppData\Local\Programs\Python\Python312\Lib\site-packages\pandas\core\indexes\base.py", line 3805, in get_loc
    return self._engine.get_loc(casted_key)
           ^^^^^^^^^^^^^^^^^^^^^^^^^^^^^^^^
  File "index.pyx", line 167, in pandas._libs.index.IndexEngine.get_loc
  File "index.pyx", line 196, in pandas._libs.index.IndexEngine.get_loc
  File "pandas\\_libs\\hashtable_class_helper.pxi", line 7081, in pandas._libs.hashtable.PyObjectHashTable.get_item
  File "pandas\\_libs\\hashtable_class_helper.pxi", line 7089, in pandas._libs.hashtable.PyObjectHashTable.get_item
KeyError: 'Date'

The above exception was the direct cause of the following exception:

Traceback (most recent call last):
  File "d:\programming projects\.py projects\DailyCheckIn\Daily Check In.py", line 107, in <module>
    __main__()
  File "d:\programming projects\.py projects\DailyCheckIn\Daily Check In.py", line 78, in __main__
    print(dataset.loc[:, 'Date'])
          ~~~~~~~~~~~^^^^^^^^^^^
  File "C:\Users\arkot\AppData\Local\Programs\Python\Python312\Lib\site-packages\pandas\core\indexing.py", line 1184, in __getitem__
    return self._getitem_tuple(key)
           ^^^^^^^^^^^^^^^^^^^^^^^^
  File "C:\Users\arkot\AppData\Local\Programs\Python\Python312\Lib\site-packages\pandas\core\indexing.py", line 1368, in _getitem_tuple
    return self._getitem_lowerdim(tup)
           ^^^^^^^^^^^^^^^^^^^^^^^^^^^
  File "C:\Users\arkot\AppData\Local\Programs\Python\Python312\Lib\site-packages\pandas\core\indexing.py", line 1065, in _getitem_lowerdim
    section = self._getitem_axis(key, axis=i)
              ^^^^^^^^^^^^^^^^^^^^^^^^^^^^^^^
  File "C:\Users\arkot\AppData\Local\Programs\Python\Python312\Lib\site-packages\pandas\core\indexing.py", line 1431, in _getitem_axis
    return self._get_label(key, axis=axis)
           ^^^^^^^^^^^^^^^^^^^^^^^^^^^^^^^
  File "C:\Users\arkot\AppData\Local\Programs\Python\Python312\Lib\site-packages\pandas\core\indexing.py", line 1381, in _get_label
    return self.obj.xs(label, axis=axis)
           ^^^^^^^^^^^^^^^^^^^^^^^^^^^^^
  File "C:\Users\arkot\AppData\Local\Programs\Python\Python312\Lib\site-packages\pandas\core\generic.py", line 4287, in xs
    return self[key]
           ~~~~^^^^^
  File "C:\Users\arkot\AppData\Local\Programs\Python\Python312\Lib\site-packages\pandas\core\frame.py", line 4102, in __getitem__
    indexer = self.columns.get_loc(key)
              ^^^^^^^^^^^^^^^^^^^^^^^^^
  File "C:\Users\arkot\AppData\Local\Programs\Python\Python312\Lib\site-packages\pandas\core\indexes\base.py", line 3812, in get_loc
    raise KeyError(key) from err
KeyError: 'Date'
KeyError: 'Time Slept'
